Workbook

Sheet 안내
A1: 항목 | B1: 내용
A2: MFA 파일럿 연구자 검토표 | B2: 2020–2025년, 연도별 10개, 총 60개
A3: 목적 | B3: 대량 MFA 전에 음성·전사·TextGrid·형태소·발음 참조·화자 연결을 사람이 확인하고 기록
A4: 사용 순서 | B4: 검토입력 시트에서 WAV와 TextGrid를 열고 노란 입력 열을 드롭다운으로 판정
A5: 파일 링크 | B5: 이 워크북을 7_review_by_year_20260725 폴더 안에서 열어야 상대경로 링크가 작동
A6: 판정 기준 | B6: 양호/일치 = 그대로 사용 가능, 수정 필요/불일치 = 대량 작업 전에 원인 분류 필요
A7: 판단 불가 | B7: 현재 자료만으로 판정할 수 없을 때 사용하며 비고에 이유 기록
A8: 공동 참여자 | B8: co_speaker_ids는 같은 대화 문서의 다른 참여자이며 직접 수신자(addressee) 표지가 아님
A9: 발음 참조 | B9: pron_reference는 철자·규칙 기반 검색 보조 정보이며 사전 발음 또는 실제 음성 실현 판정값이 아님
A10: 원본 보존 | B10: 원본인덱스 시트는 INDEX_ALL.csv의 값이며 검토 결과와 분리
A11: 자동 집계 | B11: 진행요약은 검토입력 시트의 판정값을 수식으로 집계하며 Excel에서 열 때 재계산
A12: 우선 사례 1 | B12: SDRW2300001955.1.1.164 — 파일 찾기와 음성·전사 일치 확인
... A16: 생성 시각 | B16: 2026-07-25T11:04:05+09:00
A17: 원본 발화 수 | B17: 60

Sheet 검토입력
A1: 번호 | B1: 우선 확인 | C1: 연도 | D1: 발화 ID | E1: 화자 ID | F1: 공동 참여자 ID | G1: 정규형 | H1: 원문 | I1: 발음 참조 | J1: WAV | K1: TextGrid | L1: CSV | M1: LAB | N1: 음성-문장 일치 | O1: words 정렬 | P1: phones 정렬 | Q1: morphemes 정렬 | R1: 처음·끝 경계 | S1: original/pron 표시 | T1: 화자·참여자 ID | U1: 종합 판정 | V1: 재검토 | W1: 비고 | X1: 검토자 | Y1: 검토일 | Z1: 검토 완료 | AA1: 대화 ID | AB1: 전체 화자 ID | AC1: 발음 근거 | AD1: 자동 tier 경고 | AE1: original 정렬 상태 | AF1: 발음 tier 정렬 상태 | AG1: 원본 행 번호
A2: 1 | C2: 2020 | D2: SDRW2000000762.1.1.178 | E2: SD2001178 | F2: SD2001179 | G2: 근데 그 행위 자체가 | H2: 근데 그 행위 자체가 | I2: 근데 그 행위 자체가 | J2: WAV 열기 | K2: TextGrid 열기 | L2: CSV 열기 | M2: LAB 열기 | Z2: =IF(COUNTA(N2:U2)=8,"완료","미완료") | AA2: SDRW2000000762.1 | AB2: SD2001178 | SD2001179 | AC2: form_rule_prediction | AE2: all_lexical_slots | AF2: all_lexical_slots | AG2: 2
A3: 2 | C3: 2020 | D3: SDRW2000000762.1.1.193 | E3: SD2001178 | F3: SD2001179 | G3: 임차인이 임차를 하고 있 있는 와중에도 | H3: 임차인이 임차를 하고 -있- 있는 와중에도 | I3: 임차이니 임차를 하고 읻 인는 와중에도 | J3: WAV 열기 | K3: TextGrid 열기 | L3: CSV 열기 | M3: LAB 열기 | Z3: =IF(COUNTA(N3:U3)=8,"완료","미완료") | AA3: SDRW2000000762.1 | AB3: SD2001178 | SD2001179 | AC3: form_rule_prediction | AE3: all_lexical_slots | AF3: all_lexical_slots | AG3: 3
A4: 3 | C4: 2020 | D4: SDRW2000001052.1.1.105 | E4: SD2001202 | F4: SD2001203 | G4: 이런 걸 | H4: 이런 걸 | I4: 이런 걸 | J4: WAV 열기 | K4: TextGrid 열기 | L4: CSV 열기 | M4: LAB 열기 | Z4: =IF(COUNTA(N4:U4)=8,"완료","미완료") | AA4: SDRW2000001052.1 | AB4: SD2001202 | SD2001203 | AC4: form_rule_prediction | AE4: all_lexical_slots | AF4: all_lexical_slots | AG4: 4
A5: 4 | C5: 2020 | D5: SDRW2000001052.1.1.200 | E5: SD2001202 | F5: SD2001203 | G5: 그런 발주를 맡기면서 | H5: 그런 발주를 맡기면서 | I5: 그런 발주를 맏끼면서 | J5: WAV 열기 | K5: TextGrid 열기 | L5: CSV 열기 | M5: LAB 열기 | Z5: =IF(COUNTA(N5:U5)=8,"완료","미완료") | AA5: SDRW2000001052.1 | AB5: SD2001202 | SD2001203 | AC5: form_rule_prediction | AE5: all_lexical_slots | AF5: all_lexical_slots | AG5: 5
A6: 5 | C6: 2020 | D6: SDRW2000001477.1.1.288 | E6: SD2001756 | F6: SD2001757 | G6: 갖고 있습니다. | H6: 갖고 있습니다. | I6: 갇꼬 읻씀니다 | J6: WAV 열기 | K6: TextGrid 열기 | L6: CSV 열기 | M6: LAB 열기 | Z6: =IF(COUNTA(N6:U6)=8,"완료","미완료") | AA6: SDRW2000001477.1 | AB6: SD2001756 | SD2001757 | AC6: form_rule_prediction | AE6: all_lexical_slots | AF6: all_lexical_slots | AG6: 6
A7: 6 | C7: 2020 | D7: SDRW2000001477.1.1.146 | E7: SD2001756 | F7: SD2001757 | G7: 봉준호 감독이 | H7: 봉준호 감독이 | I7: 봉준호 감도기 | J7: WAV 열기 | K7: TextGrid 열기 | L7: CSV 열기 | M7: LAB 열기 | Z7: =IF(COUNTA(N7:U7)=8,"완료","미완료") | AA7: SDRW2000001477.1 | AB7: SD2001756 | SD2001757 | AC7: form_rule_prediction | AE7: all_lexical_slots | AF7: all_lexical_slots | AG7: 7
A8: 7 | C8: 2020 | D8: SDRW2000001593.1.1.301 | E8: SD2001926 | F8: SD2001936 | G8: 드린 선물이 기억에 남는 게 있다면 | H8: 드린 선물이 기억에 남는 게 있다면 | I8: 드린 선무리 기어게 남는 게 읻따면 | J8: WAV 열기 | K8: TextGrid 열기 | L8: CSV 열기 | M8: LAB 열기 | Z8: =IF(COUNTA(N8:U8)=8,"완료","미완료") | AA8: SDRW2000001593.1 | AB8: SD2001926 | SD2001936 | AC8: form_rule_prediction | AE8: all_lexical_slots | AF8: all_lexical_slots | AG8: 8
A9: 8 | C9: 2020 | D9: SDRW2000001593.1.1.325 | E9: SD2001926 | F9: SD2001936 | G9: 웃어른 | H9: 웃어른 | I9: 우서른 | J9: WAV 열기 | K9: TextGrid 열기 | L9: CSV 열기 | M9: LAB 열기 | Z9: =IF(COUNTA(N9:U9)=8,"완료","미완료") | AA9: SDRW2000001593.1 | AB9: SD2001926 | SD2001936 | AC9: form_rule_prediction | AE9: all_lexical_slots | AF9: all_lexical_slots | AG9: 9
A10: 9 | C10: 2020 | D10: SDRW2000001640.1.1.364 | E10: SD2001982 | F10: SD2001983 | G10: 뜨거운 물 좀 퍼가도 되지 | H10: 뜨거운 물 좀 퍼가도 되지 | I10: 뜨거운 물 좀 퍼가도 되지 | J10: WAV 열기 | K10: TextGrid 열기 | L10: CSV 열기 | M10: LAB 열기 | Z10: =IF(COUNTA(N10:U10)=8,"완료","미완료") | AA10: SDRW2000001640.1 | AB10: SD2001982 | SD2001983 | AC10: form_rule_prediction | AE10: all_lexical_slots | AF10: all_lexical_slots | AG10: 10
A11: 10 | C11: 2020 | D11: SDRW2000001640.1.1.361 | E11: SD2001982 | F11: SD2001983 | G11: 전기세도 들고 | H11: 전기세도 들고 | I11: 전기세도 들고 | J11: WAV 열기 | K11: TextGrid 열기 | L11: CSV 열기 | M11: LAB 열기 | Z11: =IF(COUNTA(N11:U11)=8,"완료","미완료") | AA11: SDRW2000001640.1 | AB11: SD2001982 | SD2001983 | AC11: form_rule_prediction | AE11: all_lexical_slots | AF11: all_lexical_slots | AG11: 11
A12: 11 | C12: 2021 | D12: SDRW2100001431.1.1.103 | E12: SD2100792 | F12: SD2110791 | G12: 되게 애매모호해 진 경우가 되게 많습니다. | H12: 되게 애매모호해 진 경우가 되게 많습니다. | I12: 되게 애매모호해 진 경우가 되게 만씀니다 | J12: WAV 열기 | K12: TextGrid 열기 | L12: CSV 열기 | M12: LAB 열기 | Z12: =IF(COUNTA(N12:U12)=8,"완료","미완료") | AA12: SDRW2100001431.1 | AB12: SD2100792 | SD2110791 | AC12: form_rule_prediction | AE12: labeled_word_slots | AF12: labeled_word_slots | AG12: 12
A13: 12 | C13: 2021 | D13: SDRW2100001431.1.1.135 | E13: SD2100792 | F13: SD2110791 | G13: 좀 | H13: 쫌 | I13: 좀 | J13: WAV 열기 | K13: TextGrid 열기 | L13: CSV 열기 | M13: LAB 열기 | Z13: =IF(COUNTA(N13:U13)=8,"완료","미완료") | AA13: SDRW2100001431.1 | AB13: SD2100792 | SD2110791 | AC13: form_rule_prediction | AE13: all_lexical_slots | AF13: all_lexical_slots | AG13: 13
... A15: 14 | C15: 2021 | D15: SDRW2100003457.1.1.200 | E15: SD2100911 | F15: SD2100912 | G15: 많은 범죄들 | H15: 많은 범죄들 | I15: 마는 범죄들 | J15: WAV 열기 | K15: TextGrid 열기 | L15: CSV 열기 | M15: LAB 열기 | Z15: =IF(COUNTA(N15:U15)=8,"완료","미완료") | AA15: SDRW2100003457.1 | AB15: SD2100911 | SD2100912 | AC15: form_rule_prediction | AE15: labeled_word_slots | AF15: labeled_word_slots | AG15: 15
A16: 15 | C16: 2021 | D16: SDRW2100001607.1.1.228 | E16: SD2101608 | F16: SD2101607 | G16: 상관없나? | H16: 상관없나? {laughing} | I16: 상과넘나 | J16: WAV 열기 | K16: TextGrid 열기 | L16: CSV 열기 | M16: LAB 열기 | Z16: =IF(COUNTA(N16:U16)=8,"완료","미완료") | AA16: SDRW2100001607.1 | AB16: SD2101607 | SD2101608 | AC16: form_rule_prediction | AD16: original_form: tokens=2, lexical_slots=1, labeled_slots=1 | AE16: utterance_fallback | AF16: all_lexical_slots | AG16: 16
A17: 16 | C17: 2021 | D17: SDRW2100001607.1.1.485 | E17: SD2101608 | F17: SD2101607 | G17: 친구 간 선호 이게 뭔 뜻이지? | H17: 친구 간 선호 이게 뭔 뜻이지? | I17: 친구 간 선호 이게 뭔 뜨시지 | J17: WAV 열기 | K17: TextGrid 열기 | L17: CSV 열기 | M17: LAB 열기 | Z17: =IF(COUNTA(N17:U17)=8,"완료","미완료") | AA17: SDRW2100001607.1 | AB17: SD2101607 | SD2101608 | AC17: form_rule_prediction | AE17: all_lexical_slots | AF17: all_lexical_slots | AG17: 17
A18: 17 | C18: 2021 | D18: SDRW2100001646.1.1.113 | E18: SD2101640 | F18: SD2101639 | G18: 아. | H18: 아. | I18: 아 | J18: WAV 열기 | K18: TextGrid 열기 | L18: CSV 열기 | M18: LAB 열기 | Z18: =IF(COUNTA(N18:U18)=8,"완료","미완료") | AA18: SDRW2100001646.1 | AB18: SD2101639 | SD2101640 | AC18: form_rule_prediction | AE18: all_lexical_slots | AF18: all_lexical_slots | AG18: 18
A19: 18 | C19: 2021 | D19: SDRW2100001646.1.1.269 | E19: SD2101640 | F19: SD2101639 | G19: 맞아. | H19: 맞아. | I19: 마자 | J19: WAV 열기 | K19: TextGrid 열기 | L19: CSV 열기 | M19: LAB 열기 | Z19: =IF(COUNTA(N19:U19)=8,"완료","미완료") | AA19: SDRW2100001646.1 | AB19: SD2101639 | SD2101640 | AC19: form_rule_prediction | AE19: all_lexical_slots | AF19: all_lexical_slots | AG19: 19
A20: 19 | C20: 2021 | D20: SDRW2100004382.1.1.141 | E20: SD2102409 | F20: SD2102410 | G20: 나이가 들어서 어느 정도 됐을 때는 음 결혼 상대자가 있었으면 좋겠어. | H20: 나이가 들어서 어느 정도 됐을 때는 음 결혼 상대자가 있었으면 좋겠어. | I20: 나이가 드러서 어느 정도 돼쓸 때는 음 결혼 상대자가 이써쓰면 조케써 | J20: WAV 열기 | K20: TextGrid 열기 | L20: CSV 열기 | M20: LAB 열기 | Z20: =IF(COUNTA(N20:U20)=8,"완료","미완료") | AA20: SDRW2100004382.1 | AB20: SD2102409 | SD2102410 | AC20: form_rule_prediction | AE20: labeled_word_slots | AF20: labeled_word_slots | AG20: 20
A21: 20 | C21: 2021 | D21: SDRW2100004382.1.1.298 | E21: SD2102409 | F21: SD2102410 | G21: 그냥 트래킹 가다가 지나간 거니까 거기서 그냥 꽃 사서 | H21: 그냥 트래킹 가다가 지나간 거니까 거기서 그냥 꽃 사서 | I21: 그냥 트래킹 가다가 지나간 거니까 거기서 그냥 꼳 사서 | J21: WAV 열기 | K21: TextGrid 열기 | L21: CSV 열기 | M21: LAB 열기 | Z21: =IF(COUNTA(N21:U21)=8,"완료","미완료") | AA21: SDRW2100004382.1 | AB21: SD2102409 | SD2102410 | AC21: form_rule_prediction | AE21: labeled_word_slots | AF21: labeled_word_slots | AG21: 21
A22: 21 | C22: 2022 | D22: SDRW2200002419.1.1.72 | E22: SD2201149 | F22: SD2201150 | G22: 철판 올리고 나르고 그게 엄청 힘들었는데? | H22: 철판 올르고 날르고 그게 엄청 힘들었는데? | I22: 철판 올리고 나르고 그게 엄청 힘드런는데 | J22: WAV 열기 | K22: TextGrid 열기 | L22: CSV 열기 | M22: LAB 열기 | Z22: =IF(COUNTA(N22:U22)=8,"완료","미완료") | AA22: SDRW2200002419.1 | AB22: SD2201149 | SD2201150 | AC22: form_rule_prediction | AE22: labeled_word_slots | AF22: labeled_word_slots | AG22: 22
A23: 22 | C23: 2022 | D23: SDRW2200002419.1.1.411 | E23: SD2201149 | F23: SD2201150 | G23: 무거운 거 다 내가 쌓아야 되고 옮겨야 되고 | H23: 무거운 거 다 내가 쌓아야 되고 옮겨야 되고 | I23: 무거운 거 다 내가 싸아야 되고 옴겨야 되고 | J23: WAV 열기 | K23: TextGrid 열기 | L23: CSV 열기 | M23: LAB 열기 | Z23: =IF(COUNTA(N23:U23)=8,"완료","미완료") | AA23: SDRW2200002419.1 | AB23: SD2201149 | SD2201150 | AC23: form_rule_prediction | AE23: labeled_word_slots | AF23: labeled_word_slots | AG23: 23
A24: 23 | C24: 2022 | D24: SDRW2200000836.1.1.61 | E24: SD2201235 | F24: SD2201236 | G24: 꽃에 모양은 어땠어? | H24: 꽃에 모양은 어땠어? | I24: 꼬체 모양은 어때써 | J24: WAV 열기 | K24: TextGrid 열기 | L24: CSV 열기 | M24: LAB 열기 | Z24: =IF(COUNTA(N24:U24)=8,"완료","미완료") | AA24: SDRW2200000836.1 | AB24: SD2201235 | SD2201236 | AC24: form_rule_prediction | AE24: labeled_word_slots | AF24: labeled_word_slots | AG24: 24
A25: 24 | C25: 2022 | D25: SDRW2200000836.1.1.119 | E25: SD2201235 | F25: SD2201236 | G25: 그렇네 그 정도만 돼도 좋을 텐데 철물 구조 그거 되게 비쌌을 텐데. | H25: 그렇네 그 정도만 돼도 좋을 텐데 철물 구조 그거 되게 비쌌을 텐데. | I25: 그런네 그 정도만 돼도 조을 텐데 철물 구조 그거 되게 비싸쓸 텐데 | J25: WAV 열기 | K25: TextGrid 열기 | L25: CSV 열기 | M25: LAB 열기 | Z25: =IF(COUNTA(N25:U25)=8,"완료","미완료") | AA25: SDRW2200000836.1 | AB25: SD2201235 | SD2201236 | AC25: form_rule_prediction | AE25: labeled_word_slots | AF25: labeled_word_slots | AG25: 25
A26: 25 | C26: 2022 | D26: SDRW2200001237.1.1.223 | E26: SD2201782 | F26: SD2201781 | G26: 나는 연락을 받았는데 자기는 안 가고 싶어하고 | H26: 나는 연락을 받았는데 자기는 안 가고 싶어하고 | I26: 나는 열라글 바단는데 자기는 안 가고 시퍼하고 | J26: WAV 열기 | K26: TextGrid 열기 | L26: CSV 열기 | M26: LAB 열기 | Z26: =IF(COUNTA(N26:U26)=8,"완료","미완료") | AA26: SDRW2200001237.1 | AB26: SD2201781 | SD2201782 | AC26: form_rule_prediction | AE26: labeled_word_slots | AF26: labeled_word_slots | AG26: 26
A27: 26 | C27: 2022 | D27: SDRW2200001237.1.1.105 | E27: SD2201782 | F27: SD2201781 | G27: 며느리 사랑은 시아버지야. | H27: 며느리 사랑은 시아버지야. | I27: 며느리 사랑은 시아버지야 | J27: WAV 열기 | K27: TextGrid 열기 | L27: CSV 열기 | M27: LAB 열기 | Z27: =IF(COUNTA(N27:U27)=8,"완료","미완료") | AA27: SDRW2200001237.1 | AB27: SD2201781 | SD2201782 | AC27: form_rule_prediction | AE27: all_lexical_slots | AF27: all_lexical_slots | AG27: 27
A28: 27 | C28: 2022 | D28: SDRW2200001570.1.1.280 | E28: SD2202054 | F28: SD2202055 | G28: 그렇다고 우리 세금을 낼 수 이 우예 | H28: 그렇다고 우리 세금을 낼 수 이 ((우예)) | I28: 그러타고 우리 세그믈 낼 수 이 우예 | J28: WAV 열기 | K28: TextGrid 열기 | L28: CSV 열기 | M28: LAB 열기 | Z28: =IF(COUNTA(N28:U28)=8,"완료","미완료") | AA28: SDRW2200001570.1 | AB28: SD2202054 | SD2202055 | AC28: form_rule_prediction | AE28: labeled_word_slots | AF28: labeled_word_slots | AG28: 28
... A36: 35 | C36: 2023 | D36: SDRW2300001859.1.1.109 | E36: SD2301983 | F36: SD2301982 | G36: 어떻게 두시고 투자를 하시는 타입이신가요? | H36: 어떻게 두시고 투자를 하시는 타입이신가요? | I36: 어떠케 두시고 투자를 하시는 타이비신가요 | J36: WAV 열기 | K36: TextGrid 열기 | L36: CSV 열기 | M36: LAB 열기 | Z36: =IF(COUNTA(N36:U36)=8,"완료","미완료") | AA36: SDRW2300001859.1 | AB36: SD2301982 | SD2301983 | AC36: form_rule_prediction | AE36: labeled_word_slots | AF36: labeled_word_slots | AG36: 36
A37: 36 | C37: 2023 | D37: SDRW2300001859.1.1.108 | E37: SD2301983 | F37: SD2301982 | G37: 장기 단기 이런 기간을 | H37: 장기 단기 이런 {laughing} 기간을 | I37: 장기 단기 이런 기가늘 | J37: WAV 열기 | K37: TextGrid 열기 | L37: CSV 열기 | M37: LAB 열기 | Z37: =IF(COUNTA(N37:U37)=8,"완료","미완료") | AA37: SDRW2300001859.1 | AB37: SD2301982 | SD2301983 | AC37: form_rule_prediction | AD37: original_form: tokens=5, lexical_slots=7, labeled_slots=4 | AE37: utterance_fallback | AF37: labeled_word_slots | AG37: 37
A38: 37 | B38: 이전 검토에서 찾기 어려웠던 발화 | C38: 2023 | D38: SDRW2300001955.1.1.164 | E38: SD2302149 | F38: SD2302148 | G38: 어 접근하려고 좀 노력을 하고 있습니다. | H38: 어~ 접근할려고 쫌 노력을 하고 있습니다. | I38: 어 접끈하려고 좀 노려글 하고 읻씀니다 | J38: WAV 열기 | K38: TextGrid 열기 | L38: CSV 열기 | M38: LAB 열기 | Z38: =IF(COUNTA(N38:U38)=8,"완료","미완료") | AA38: SDRW2300001955.1 | AB38: SD2302148 | SD2302149 | AC38: form_rule_prediction | AE38: labeled_word_slots | AF38: labeled_word_slots | AG38: 38
A39: 38 | C39: 2023 | D39: SDRW2300001955.1.1.11 | E39: SD2302149 | F39: SD2302148 | G39: 어 월세 전세 이런 뭐 매물들을 다루다 보니까 | H39: 어~ 월세 전세 이런 뭐~ 매물들을 다루다 보니까 | I39: 어 월세 전세 이런 뭐 매물드를 다루다 보니까 | J39: WAV 열기 | K39: TextGrid 열기 | L39: CSV 열기 | M39: LAB 열기 | Z39: =IF(COUNTA(N39:U39)=8,"완료","미완료") | AA39: SDRW2300001955.1 | AB39: SD2302148 | SD2302149 | AC39: form_rule_prediction | AE39: labeled_word_slots | AF39: labeled_word_slots | AG39: 39
A40: 39 | B40: 숫자 1/일 발음 참조·화자 정보 확인 | C40: 2023 | D40: SDRW2300000891.1.1.331 | E40: SD2310934 | F40: SD2300935 | G40: 무조건 1층으로 된 집에서 살고 싶어. | H40: 무조건 일 층으로 된 집에서 살고 싶어. | I40: 무조건 일 층으로 된 지베서 살고 시퍼 | J40: WAV 열기 | K40: TextGrid 열기 | L40: CSV 열기 | M40: LAB 열기 | Z40: =IF(COUNTA(N40:U40)=8,"완료","미완료") | AA40: SDRW2300000891.1 | AB40: SD2300935 | SD2310934 | AC40: original_form_placeholder_resolution | AE40: all_lexical_slots | AF40: all_lexical_slots | AG40: 40
A41: 40 | C41: 2023 | D41: SDRW2300000891.1.1.229 | E41: SD2310934 | F41: SD2300935 | G41: 가지고 싶은 소품이나 아니면 이런 걸 놓을 공간이 있으면 좋겠다. | H41: 가지고 싶은 소품이나 아니면 이런 걸 놓을 공간이 있으면 좋겠다. | I41: 가지고 시픈 소푸미나 아니면 이런 걸 노을 공가니 이쓰면 조켇따 | J41: WAV 열기 | K41: TextGrid 열기 | L41: CSV 열기 | M41: LAB 열기 | Z41: =IF(COUNTA(N41:U41)=8,"완료","미완료") | AA41: SDRW2300000891.1 | AB41: SD2300935 | SD2310934 | AC41: form_rule_prediction | AE41: labeled_word_slots | AF41: labeled_word_slots | AG41: 41
A42: 41 | C42: 2024 | D42: SDRW2400001098.1.1.64 | E42: SD2400795 | F42: SD2400796 | G42: 그 요즘 택배 중에 그렇게 어 | H42: 그 요즘 택배 중에 그릏게 어~ | I42: 그 요즘 택빼 중에 그러케 어 | J42: WAV 열기 | K42: TextGrid 열기 | L42: CSV 열기 | M42: LAB 열기 | Z42: =IF(COUNTA(N42:U42)=8,"완료","미완료") | AA42: SDRW2400001098.1 | AB42: SD2400795 | SD2400796 | AC42: form_rule_prediction | AE42: labeled_word_slots | AF42: labeled_word_slots | AG42: 42
A43: 42 | C43: 2024 | D43: SDRW2400001098.1.1.92 | E43: SD2400795 | F43: SD2400796 | G43: 어 그게 이제 어도비에서 제공하는 모든 프로그램을 이용할 수 있는 이제 | H43: 어 그게 이제 어도비에서 제공하는 모든 프로그램을 이용할 수 있는 이제 | I43: 어 그게 이제 어도비에서 제공하는 모든 프로그래믈 이용할 수 인는 이제 | J43: WAV 열기 | K43: TextGrid 열기 | L43: CSV 열기 | M43: LAB 열기 | Z43: =IF(COUNTA(N43:U43)=8,"완료","미완료") | AA43: SDRW2400001098.1 | AB43: SD2400795 | SD2400796 | AC43: form_rule_prediction | AE43: labeled_word_slots | AF43: labeled_word_slots | AG43: 43
A44: 43 | C44: 2024 | D44: SDRW2400000324.1.1.170 | E44: SD2400841 | F44: SD2400839 | SD2400840 | G44: 나는 약간 그 스카이 캐슬의 내용 중에서 이제 어떤 한 아이 아이들의 어머니가 아버지에게 이제 큰 음 약간 가정 폭력 비슷한 거를 이제 당하는 장면에서 | H44: 나는 약간 그~ 스카이 캐쓸에 내용 중에서 이제 어떤 한 -아이- 아이들에 어머니가 아버지에게 이제 큰 음~ 약간 가정 폭력 비슷한 거를 이제 당하는 장면에서 | I44: 나는 약깐 그 스카이 캐스릐 내용 중에서 이제 어떤 한 아이 아이드릐 어머니가 아버지에게 이제 큰 음 약깐 가정 폭력 비스탄 거를 이제 당하는 장며네서 | J44: WAV 열기 | K44: TextGrid 열기 | L44: CSV 열기 | M44: LAB 열기 | Z44: =IF(COUNTA(N44:U44)=8,"완료","미완료") | AA44: SDRW2400000324.1 | AB44: SD2400839 | SD2400840 | SD2400841 | AC44: form_rule_prediction | AE44: labeled_word_slots | AF44: labeled_word_slots | AG44: 44
A45: 44 | C45: 2024 | D45: SDRW2400000324.1.1.30 | E45: SD2400841 | F45: SD2400839 | SD2400840 | G45: 그것도 해리 포터 작가와 같은 롤랭 롤랭 조인 뭐 이름은 잘 모르겠지만 | H45: 그것도 해리 포터 작가와 같은 롤랭 롤랭 조인 뭐~ 이름은 잘 모르겠지만 | I45: 그걷또 해리 포터 작까와 가튼 롤랭 롤랭 조인 뭐 이르믄 잘 모르겓찌만 | J45: WAV 열기 | K45: TextGrid 열기 | L45: CSV 열기 | M45: LAB 열기 | Z45: =IF(COUNTA(N45:U45)=8,"완료","미완료") | AA45: SDRW2400000324.1 | AB45: SD2400839 | SD2400840 | SD2400841 | AC45: form_rule_prediction | AE45: labeled_word_slots | AF45: labeled_word_slots | AG45: 45
A46: 45 | C46: 2024 | D46: SDRW2400001368.1.1.121 | E46: SD2401102 | F46: SD2401101 | G46: 홈 쇼핑에서 사는 게 어려워지는 것 같아. | H46: 홈 쑈핑에서 사는 게 어려워지는 거 같애. | I46: 홈 쇼핑에서 사는 게 어려워지는 걷 가타 | J46: WAV 열기 | K46: TextGrid 열기 | L46: CSV 열기 | M46: LAB 열기 | Z46: =IF(COUNTA(N46:U46)=8,"완료","미완료") | AA46: SDRW2400001368.1 | AB46: SD2401101 | SD2401102 | AC46: form_rule_prediction | AE46: all_lexical_slots | AF46: all_lexical_slots | AG46: 46
A47: 46 | C47: 2024 | D47: SDRW2400001368.1.1.105 | E47: SD2401102 | F47: SD2401101 | G47: 혜택적인 부분도 내가 엄마가 직접적으로 듣고 바로 구매할 수 있는 | H47: 혜택적인 부분두 내가 엄마가 직접적으로 듣고 바로 구매할 수 있는 | I47: 혜택쩌긴 부분도 내가 엄마가 직쩝쩌그로 듣꼬 바로 구매할 수 인는 | J47: WAV 열기 | K47: TextGrid 열기 | L47: CSV 열기 | M47: LAB 열기 | Z47: =IF(COUNTA(N47:U47)=8,"완료","미완료") | AA47: SDRW2400001368.1 | AB47: SD2401101 | SD2401102 | AC47: form_rule_prediction | AE47: labeled_word_slots | AF47: labeled_word_slots | AG47: 47
A48: 47 | C48: 2024 | D48: SDRW2400001439.1.1.152 | E48: SD2401137 | F48: SD2401138 | G48: 어 그렇긴 해. | H48: 어 그렇긴 해. | I48: 어 그러킨 해 | J48: WAV 열기 | K48: TextGrid 열기 | L48: CSV 열기 | M48: LAB 열기 | Z48: =IF(COUNTA(N48:U48)=8,"완료","미완료") | AA48: SDRW2400001439.1 | AB48: SD2401137 | SD2401138 | AC48: form_rule_prediction | AE48: all_lexical_slots | AF48: all_lexical_slots | AG48: 48
...

Sheet 진행요약
A1: 전체 진행 요약 | B1: 값
A2: 총 발화 | B2: =COUNTA('검토입력'!$D$2:$D$61)
A3: 검토 완료 | B3: =COUNTIF('검토입력'!$Z$2:$Z$61,"완료")
A4: 진행률 | B4: =IFERROR(B3/B2,0)
A5: 통과 | B5: =COUNTIF('검토입력'!$U$2:$U$61,"통과")
A6: 수정 필요 | B6: =COUNTIF('검토입력'!$U$2:$U$61,"수정 필요")
A7: 보류 | B7: =COUNTIF('검토입력'!$U$2:$U$61,"보류")
A8: 재검토 | B8: =COUNTIF('검토입력'!$V$2:$V$61,"예")
A9: 상태 | B9: =IF(B3=B2,"전체 검토 완료","검토 진행 중")
A11: 연도 | B11: 대상 | C11: 완료 | D11: 진행률 | E11: 통과 | F11: 수정 필요 | G11: 보류
A12: 2020 | B12: =COUNTIF('검토입력'!$C$2:$C$61,A12) | C12: =COUNTIFS('검토입력'!$C$2:$C$61,A12,'검토입력'!$Z$2:$Z$61,"완료") | D12: =IFERROR(C12/B12,0) | E12: =COUNTIFS('검토입력'!$C$2:$C$61,A12,'검토입력'!$U$2:$U$61,"통과") | F12: =COUNTIFS('검토입력'!$C$2:$C$61,A12,'검토입력'!$U$2:$U$61,"수정 필요") | G12: =COUNTIFS('검토입력'!$C$2:$C$61,A12,'검토입력'!$U$2:$U$61,"보류")
A13: 2021 | B13: =COUNTIF('검토입력'!$C$2:$C$61,A13) | C13: =COUNTIFS('검토입력'!$C$2:$C$61,A13,'검토입력'!$Z$2:$Z$61,"완료") | D13: =IFERROR(C13/B13,0) | E13: =COUNTIFS('검토입력'!$C$2:$C$61,A13,'검토입력'!$U$2:$U$61,"통과") | F13: =COUNTIFS('검토입력'!$C$2:$C$61,A13,'검토입력'!$U$2:$U$61,"수정 필요") | G13: =COUNTIFS('검토입력'!$C$2:$C$61,A13,'검토입력'!$U$2:$U$61,"보류")
A14: 2022 | B14: =COUNTIF('검토입력'!$C$2:$C$61,A14) | C14: =COUNTIFS('검토입력'!$C$2:$C$61,A14,'검토입력'!$Z$2:$Z$61,"완료") | D14: =IFERROR(C14/B14,0) | E14: =COUNTIFS('검토입력'!$C$2:$C$61,A14,'검토입력'!$U$2:$U$61,"통과") | F14: =COUNTIFS('검토입력'!$C$2:$C$61,A14,'검토입력'!$U$2:$U$61,"수정 필요") | G14: =COUNTIFS('검토입력'!$C$2:$C$61,A14,'검토입력'!$U$2:$U$61,"보류")
A15: 2023 | B15: =COUNTIF('검토입력'!$C$2:$C$61,A15) | C15: =COUNTIFS('검토입력'!$C$2:$C$61,A15,'검토입력'!$Z$2:$Z$61,"완료") | D15: =IFERROR(C15/B15,0) | E15: =COUNTIFS('검토입력'!$C$2:$C$61,A15,'검토입력'!$U$2:$U$61,"통과") | F15: =COUNTIFS('검토입력'!$C$2:$C$61,A15,'검토입력'!$U$2:$U$61,"수정 필요") | G15: =COUNTIFS('검토입력'!$C$2:$C$61,A15,'검토입력'!$U$2:$U$61,"보류")
A16: 2024 | B16: =COUNTIF('검토입력'!$C$2:$C$61,A16) | C16: =COUNTIFS('검토입력'!$C$2:$C$61,A16,'검토입력'!$Z$2:$Z$61,"완료") | D16: =IFERROR(C16/B16,0) | E16: =COUNTIFS('검토입력'!$C$2:$C$61,A16,'검토입력'!$U$2:$U$61,"통과") | F16: =COUNTIFS('검토입력'!$C$2:$C$61,A16,'검토입력'!$U$2:$U$61,"수정 필요") | G16: =COUNTIFS('검토입력'!$C$2:$C$61,A16,'검토입력'!$U$2:$U$61,"보류")
A17: 2025 | B17: =COUNTIF('검토입력'!$C$2:$C$61,A17) | C17: =COUNTIFS('검토입력'!$C$2:$C$61,A17,'검토입력'!$Z$2:$Z$61,"완료") | D17: =IFERROR(C17/B17,0) | E17: =COUNTIFS('검토입력'!$C$2:$C$61,A17,'검토입력'!$U$2:$U$61,"통과") | F17: =COUNTIFS('검토입력'!$C$2:$C$61,A17,'검토입력'!$U$2:$U$61,"수정 필요") | G17: =COUNTIFS('검토입력'!$C$2:$C$61,A17,'검토입력'!$U$2:$U$61,"보류")

Sheet 원본인덱스
A1: year | B1: speaker_id | C1: session_id | D1: dialogue_id | E1: dialogue_speaker_ids | F1: n_dialogue_speakers | G1: co_speaker_ids | H1: n_co_speakers | I1: utt_id | J1: form | K1: original_form | L1: pron_pred_hangul_existing | M1: pron_reference_form | N1: pron_reference_hangul | O1: pron_reference_source | P1: pron_reference_status | Q1: original_form_align_status | R1: pron_reference_align_status | S1: tier_warning | T1: wav_relpath | U1: lab_relpath | V1: textgrid_relpath | W1: csv_relpath | X1: review_status | Y1: review_note
A2: 2020 | B2: SD2001178 | C2: SDRW2000000762 | D2: SDRW2000000762.1 | E2: SD2001178 | SD2001179 | F2: 2 | G2: SD2001179 | H2: 1 | I2: SDRW2000000762.1.1.178 | J2: 근데 그 행위 자체가 | K2: 근데 그 행위 자체가 | L2: 근데 그 행위 자체가 | M2: 근데 그 행위 자체가 | N2: 근데 그 행위 자체가 | O2: form_rule_prediction | P2: resolved_form | Q2: all_lexical_slots | R2: all_lexical_slots | T2: 2020\SDRW2000000762.1.1.178.wav | U2: 2020\SDRW2000000762.1.1.178.lab | V2: 2020\SDRW2000000762.1.1.178.TextGrid | W2: 2020\SDRW2000000762.1.1.178.csv
A3: 2020 | B3: SD2001178 | C3: SDRW2000000762 | D3: SDRW2000000762.1 | E3: SD2001178 | SD2001179 | F3: 2 | G3: SD2001179 | H3: 1 | I3: SDRW2000000762.1.1.193 | J3: 임차인이 임차를 하고 있 있는 와중에도 | K3: 임차인이 임차를 하고 -있- 있는 와중에도 | L3: 임차이니 임차를 하고 읻 인는 와중에도 | M3: 임차인이 임차를 하고 있 있는 와중에도 | N3: 임차이니 임차를 하고 읻 인는 와중에도 | O3: form_rule_prediction | P3: resolved_form | Q3: all_lexical_slots | R3: all_lexical_slots | T3: 2020\SDRW2000000762.1.1.193.wav | U3: 2020\SDRW2000000762.1.1.193.lab | V3: 2020\SDRW2000000762.1.1.193.TextGrid | W3: 2020\SDRW2000000762.1.1.193.csv
A4: 2020 | B4: SD2001202 | C4: SDRW2000001052 | D4: SDRW2000001052.1 | E4: SD2001202 | SD2001203 | F4: 2 | G4: SD2001203 | H4: 1 | I4: SDRW2000001052.1.1.105 | J4: 이런 걸 | K4: 이런 걸 | L4: 이런 걸 | M4: 이런 걸 | N4: 이런 걸 | O4: form_rule_prediction | P4: resolved_form | Q4: all_lexical_slots | R4: all_lexical_slots | T4: 2020\SDRW2000001052.1.1.105.wav | U4: 2020\SDRW2000001052.1.1.105.lab | V4: 2020\SDRW2000001052.1.1.105.TextGrid | W4: 2020\SDRW2000001052.1.1.105.csv
A5: 2020 | B5: SD2001202 | C5: SDRW2000001052 | D5: SDRW2000001052.1 | E5: SD2001202 | SD2001203 | F5: 2 | G5: SD2001203 | H5: 1 | I5: SDRW2000001052.1.1.200 | J5: 그런 발주를 맡기면서 | K5: 그런 발주를 맡기면서 | L5: 그런 발주를 맏끼면서 | M5: 그런 발주를 맡기면서 | N5: 그런 발주를 맏끼면서 | O5: form_rule_prediction | P5: resolved_form | Q5: all_lexical_slots | R5: all_lexical_slots | T5: 2020\SDRW2000001052.1.1.200.wav | U5: 2020\SDRW2000001052.1.1.200.lab | V5: 2020\SDRW2000001052.1.1.200.TextGrid | W5: 2020\SDRW2000001052.1.1.200.csv
A6: 2020 | B6: SD2001756 | C6: SDRW2000001477 | D6: SDRW2000001477.1 | E6: SD2001756 | SD2001757 | F6: 2 | G6: SD2001757 | H6: 1 | I6: SDRW2000001477.1.1.288 | J6: 갖고 있습니다. | K6: 갖고 있습니다. | L6: 갇꼬 읻씀니다 | M6: 갖고 있습니다. | N6: 갇꼬 읻씀니다 | O6: form_rule_prediction | P6: resolved_form | Q6: all_lexical_slots | R6: all_lexical_slots | T6: 2020\SDRW2000001477.1.1.288.wav | U6: 2020\SDRW2000001477.1.1.288.lab | V6: 2020\SDRW2000001477.1.1.288.TextGrid | W6: 2020\SDRW2000001477.1.1.288.csv
A7: 2020 | B7: SD2001756 | C7: SDRW2000001477 | D7: SDRW2000001477.1 | E7: SD2001756 | SD2001757 | F7: 2 | G7: SD2001757 | H7: 1 | I7: SDRW2000001477.1.1.146 | J7: 봉준호 감독이 | K7: 봉준호 감독이 | L7: 봉준호 감도기 | M7: 봉준호 감독이 | N7: 봉준호 감도기 | O7: form_rule_prediction | P7: resolved_form | Q7: all_lexical_slots | R7: all_lexical_slots | T7: 2020\SDRW2000001477.1.1.146.wav | U7: 2020\SDRW2000001477.1.1.146.lab | V7: 2020\SDRW2000001477.1.1.146.TextGrid | W7: 2020\SDRW2000001477.1.1.146.csv
A8: 2020 | B8: SD2001926 | C8: SDRW2000001593 | D8: SDRW2000001593.1 | E8: SD2001926 | SD2001936 | F8: 2 | G8: SD2001936 | H8: 1 | I8: SDRW2000001593.1.1.301 | J8: 드린 선물이 기억에 남는 게 있다면 | K8: 드린 선물이 기억에 남는 게 있다면 | L8: 드린 선무리 기어게 남는 게 읻따면 | M8: 드린 선물이 기억에 남는 게 있다면 | N8: 드린 선무리 기어게 남는 게 읻따면 | O8: form_rule_prediction | P8: resolved_form | Q8: all_lexical_slots | R8: all_lexical_slots | T8: 2020\SDRW2000001593.1.1.301.wav | U8: 2020\SDRW2000001593.1.1.301.lab | V8: 2020\SDRW2000001593.1.1.301.TextGrid | W8: 2020\SDRW2000001593.1.1.301.csv
A9: 2020 | B9: SD2001926 | C9: SDRW2000001593 | D9: SDRW2000001593.1 | E9: SD2001926 | SD2001936 | F9: 2 | G9: SD2001936 | H9: 1 | I9: SDRW2000001593.1.1.325 | J9: 웃어른 | K9: 웃어른 | L9: 우서른 | M9: 웃어른 | N9: 우서른 | O9: form_rule_prediction | P9: resolved_form | Q9: all_lexical_slots | R9: all_lexical_slots | T9: 2020\SDRW2000001593.1.1.325.wav | U9: 2020\SDRW2000001593.1.1.325.lab | V9: 2020\SDRW2000001593.1.1.325.TextGrid | W9: 2020\SDRW2000001593.1.1.325.csv
A10: 2020 | B10: SD2001982 | C10: SDRW2000001640 | D10: SDRW2000001640.1 | E10: SD2001982 | SD2001983 | F10: 2 | G10: SD2001983 | H10: 1 | I10: SDRW2000001640.1.1.364 | J10: 뜨거운 물 좀 퍼가도 되지 | K10: 뜨거운 물 좀 퍼가도 되지 | L10: 뜨거운 물 좀 퍼가도 되지 | M10: 뜨거운 물 좀 퍼가도 되지 | N10: 뜨거운 물 좀 퍼가도 되지 | O10: form_rule_prediction | P10: resolved_form | Q10: all_lexical_slots | R10: all_lexical_slots | T10: 2020\SDRW2000001640.1.1.364.wav | U10: 2020\SDRW2000001640.1.1.364.lab | V10: 2020\SDRW2000001640.1.1.364.TextGrid | W10: 2020\SDRW2000001640.1.1.364.csv
A11: 2020 | B11: SD2001982 | C11: SDRW2000001640 | D11: SDRW2000001640.1 | E11: SD2001982 | SD2001983 | F11: 2 | G11: SD2001983 | H11: 1 | I11: SDRW2000001640.1.1.361 | J11: 전기세도 들고 | K11: 전기세도 들고 | L11: 전기세도 들고 | M11: 전기세도 들고 | N11: 전기세도 들고 | O11: form_rule_prediction | P11: resolved_form | Q11: all_lexical_slots | R11: all_lexical_slots | T11: 2020\SDRW2000001640.1.1.361.wav | U11: 2020\SDRW2000001640.1.1.361.lab | V11: 2020\SDRW2000001640.1.1.361.TextGrid | W11: 2020\SDRW2000001640.1.1.361.csv
A12: 2021 | B12: SD2100792 | C12: SDRW2100001431 | D12: SDRW2100001431.1 | E12: SD2100792 | SD2110791 | F12: 2 | G12: SD2110791 | H12: 1 | I12: SDRW2100001431.1.1.103 | J12: 되게 애매모호해 진 경우가 되게 많습니다. | K12: 되게 애매모호해 진 경우가 되게 많습니다. | L12: 되게 애매모호해 진 경우가 되게 만씀니다 | M12: 되게 애매모호해 진 경우가 되게 많습니다. | N12: 되게 애매모호해 진 경우가 되게 만씀니다 | O12: form_rule_prediction | P12: resolved_form | Q12: labeled_word_slots | R12: labeled_word_slots | T12: 2021\SDRW2100001431.1.1.103.wav | U12: 2021\SDRW2100001431.1.1.103.lab | V12: 2021\SDRW2100001431.1.1.103.TextGrid | W12: 2021\SDRW2100001431.1.1.103.csv
A13: 2021 | B13: SD2100792 | C13: SDRW2100001431 | D13: SDRW2100001431.1 | E13: SD2100792 | SD2110791 | F13: 2 | G13: SD2110791 | H13: 1 | I13: SDRW2100001431.1.1.135 | J13: 좀 | K13: 쫌 | L13: 좀 | M13: 좀 | N13: 좀 | O13: form_rule_prediction | P13: resolved_form | Q13: all_lexical_slots | R13: all_lexical_slots | T13: 2021\SDRW2100001431.1.1.135.wav | U13: 2021\SDRW2100001431.1.1.135.lab | V13: 2021\SDRW2100001431.1.1.135.TextGrid | W13: 2021\SDRW2100001431.1.1.135.csv
... A15: 2021 | B15: SD2100911 | C15: SDRW2100003457 | D15: SDRW2100003457.1 | E15: SD2100911 | SD2100912 | F15: 2 | G15: SD2100912 | H15: 1 | I15: SDRW2100003457.1.1.200 | J15: 많은 범죄들 | K15: 많은 범죄들 | L15: 마는 범죄들 | M15: 많은 범죄들 | N15: 마는 범죄들 | O15: form_rule_prediction | P15: resolved_form | Q15: labeled_word_slots | R15: labeled_word_slots | T15: 2021\SDRW2100003457.1.1.200.wav | U15: 2021\SDRW2100003457.1.1.200.lab | V15: 2021\SDRW2100003457.1.1.200.TextGrid | W15: 2021\SDRW2100003457.1.1.200.csv
A16: 2021 | B16: SD2101608 | C16: SDRW2100001607 | D16: SDRW2100001607.1 | E16: SD2101607 | SD2101608 | F16: 2 | G16: SD2101607 | H16: 1 | I16: SDRW2100001607.1.1.228 | J16: 상관없나? | K16: 상관없나? {laughing} | L16: 상과넘나 | M16: 상관없나? | N16: 상과넘나 | O16: form_rule_prediction | P16: resolved_form | Q16: utterance_fallback | R16: all_lexical_slots | S16: original_form: tokens=2, lexical_slots=1, labeled_slots=1 | T16: 2021\SDRW2100001607.1.1.228.wav | U16: 2021\SDRW2100001607.1.1.228.lab | V16: 2021\SDRW2100001607.1.1.228.TextGrid | W16: 2021\SDRW2100001607.1.1.228.csv
A17: 2021 | B17: SD2101608 | C17: SDRW2100001607 | D17: SDRW2100001607.1 | E17: SD2101607 | SD2101608 | F17: 2 | G17: SD2101607 | H17: 1 | I17: SDRW2100001607.1.1.485 | J17: 친구 간 선호 이게 뭔 뜻이지? | K17: 친구 간 선호 이게 뭔 뜻이지? | L17: 친구 간 선호 이게 뭔 뜨시지 | M17: 친구 간 선호 이게 뭔 뜻이지? | N17: 친구 간 선호 이게 뭔 뜨시지 | O17: form_rule_prediction | P17: resolved_form | Q17: all_lexical_slots | R17: all_lexical_slots | T17: 2021\SDRW2100001607.1.1.485.wav | U17: 2021\SDRW2100001607.1.1.485.lab | V17: 2021\SDRW2100001607.1.1.485.TextGrid | W17: 2021\SDRW2100001607.1.1.485.csv
A18: 2021 | B18: SD2101640 | C18: SDRW2100001646 | D18: SDRW2100001646.1 | E18: SD2101639 | SD2101640 | F18: 2 | G18: SD2101639 | H18: 1 | I18: SDRW2100001646.1.1.113 | J18: 아. | K18: 아. | L18: 아 | M18: 아. | N18: 아 | O18: form_rule_prediction | P18: resolved_form | Q18: all_lexical_slots | R18: all_lexical_slots | T18: 2021\SDRW2100001646.1.1.113.wav | U18: 2021\SDRW2100001646.1.1.113.lab | V18: 2021\SDRW2100001646.1.1.113.TextGrid | W18: 2021\SDRW2100001646.1.1.113.csv
A19: 2021 | B19: SD2101640 | C19: SDRW2100001646 | D19: SDRW2100001646.1 | E19: SD2101639 | SD2101640 | F19: 2 | G19: SD2101639 | H19: 1 | I19: SDRW2100001646.1.1.269 | J19: 맞아. | K19: 맞아. | L19: 마자 | M19: 맞아. | N19: 마자 | O19: form_rule_prediction | P19: resolved_form | Q19: all_lexical_slots | R19: all_lexical_slots | T19: 2021\SDRW2100001646.1.1.269.wav | U19: 2021\SDRW2100001646.1.1.269.lab | V19: 2021\SDRW2100001646.1.1.269.TextGrid | W19: 2021\SDRW2100001646.1.1.269.csv
A20: 2021 | B20: SD2102409 | C20: SDRW2100004382 | D20: SDRW2100004382.1 | E20: SD2102409 | SD2102410 | F20: 2 | G20: SD2102410 | H20: 1 | I20: SDRW2100004382.1.1.141 | J20: 나이가 들어서 어느 정도 됐을 때는 음 결혼 상대자가 있었으면 좋겠어. | K20: 나이가 들어서 어느 정도 됐을 때는 음 결혼 상대자가 있었으면 좋겠어. | L20: 나이가 드러서 어느 정도 돼쓸 때는 음 결혼 상대자가 이써쓰면 조케써 | M20: 나이가 들어서 어느 정도 됐을 때는 음 결혼 상대자가 있었으면 좋겠어. | N20: 나이가 드러서 어느 정도 돼쓸 때는 음 결혼 상대자가 이써쓰면 조케써 | O20: form_rule_prediction | P20: resolved_form | Q20: labeled_word_slots | R20: labeled_word_slots | T20: 2021\SDRW2100004382.1.1.141.wav | U20: 2021\SDRW2100004382.1.1.141.lab | V20: 2021\SDRW2100004382.1.1.141.TextGrid | W20: 2021\SDRW2100004382.1.1.141.csv
A21: 2021 | B21: SD2102409 | C21: SDRW2100004382 | D21: SDRW2100004382.1 | E21: SD2102409 | SD2102410 | F21: 2 | G21: SD2102410 | H21: 1 | I21: SDRW2100004382.1.1.298 | J21: 그냥 트래킹 가다가 지나간 거니까 거기서 그냥 꽃 사서 | K21: 그냥 트래킹 가다가 지나간 거니까 거기서 그냥 꽃 사서 | L21: 그냥 트래킹 가다가 지나간 거니까 거기서 그냥 꼳 사서 | M21: 그냥 트래킹 가다가 지나간 거니까 거기서 그냥 꽃 사서 | N21: 그냥 트래킹 가다가 지나간 거니까 거기서 그냥 꼳 사서 | O21: form_rule_prediction | P21: resolved_form | Q21: labeled_word_slots | R21: labeled_word_slots | T21: 2021\SDRW2100004382.1.1.298.wav | U21: 2021\SDRW2100004382.1.1.298.lab | V21: 2021\SDRW2100004382.1.1.298.TextGrid | W21: 2021\SDRW2100004382.1.1.298.csv
A22: 2022 | B22: SD2201149 | C22: SDRW2200002419 | D22: SDRW2200002419.1 | E22: SD2201149 | SD2201150 | F22: 2 | G22: SD2201150 | H22: 1 | I22: SDRW2200002419.1.1.72 | J22: 철판 올리고 나르고 그게 엄청 힘들었는데? | K22: 철판 올르고 날르고 그게 엄청 힘들었는데? | L22: 철판 올리고 나르고 그게 엄청 힘드런는데 | M22: 철판 올리고 나르고 그게 엄청 힘들었는데? | N22: 철판 올리고 나르고 그게 엄청 힘드런는데 | O22: form_rule_prediction | P22: resolved_form | Q22: labeled_word_slots | R22: labeled_word_slots | T22: 2022\SDRW2200002419.1.1.72.wav | U22: 2022\SDRW2200002419.1.1.72.lab | V22: 2022\SDRW2200002419.1.1.72.TextGrid | W22: 2022\SDRW2200002419.1.1.72.csv
A23: 2022 | B23: SD2201149 | C23: SDRW2200002419 | D23: SDRW2200002419.1 | E23: SD2201149 | SD2201150 | F23: 2 | G23: SD2201150 | H23: 1 | I23: SDRW2200002419.1.1.411 | J23: 무거운 거 다 내가 쌓아야 되고 옮겨야 되고 | K23: 무거운 거 다 내가 쌓아야 되고 옮겨야 되고 | L23: 무거운 거 다 내가 싸아야 되고 옴겨야 되고 | M23: 무거운 거 다 내가 쌓아야 되고 옮겨야 되고 | N23: 무거운 거 다 내가 싸아야 되고 옴겨야 되고 | O23: form_rule_prediction | P23: resolved_form | Q23: labeled_word_slots | R23: labeled_word_slots | T23: 2022\SDRW2200002419.1.1.411.wav | U23: 2022\SDRW2200002419.1.1.411.lab | V23: 2022\SDRW2200002419.1.1.411.TextGrid | W23: 2022\SDRW2200002419.1.1.411.csv
A24: 2022 | B24: SD2201235 | C24: SDRW2200000836 | D24: SDRW2200000836.1 | E24: SD2201235 | SD2201236 | F24: 2 | G24: SD2201236 | H24: 1 | I24: SDRW2200000836.1.1.61 | J24: 꽃에 모양은 어땠어? | K24: 꽃에 모양은 어땠어? | L24: 꼬체 모양은 어때써 | M24: 꽃에 모양은 어땠어? | N24: 꼬체 모양은 어때써 | O24: form_rule_prediction | P24: resolved_form | Q24: labeled_word_slots | R24: labeled_word_slots | T24: 2022\SDRW2200000836.1.1.61.wav | U24: 2022\SDRW2200000836.1.1.61.lab | V24: 2022\SDRW2200000836.1.1.61.TextGrid | W24: 2022\SDRW2200000836.1.1.61.csv
A25: 2022 | B25: SD2201235 | C25: SDRW2200000836 | D25: SDRW2200000836.1 | E25: SD2201235 | SD2201236 | F25: 2 | G25: SD2201236 | H25: 1 | I25: SDRW2200000836.1.1.119 | J25: 그렇네 그 정도만 돼도 좋을 텐데 철물 구조 그거 되게 비쌌을 텐데. | K25: 그렇네 그 정도만 돼도 좋을 텐데 철물 구조 그거 되게 비쌌을 텐데. | L25: 그런네 그 정도만 돼도 조을 텐데 철물 구조 그거 되게 비싸쓸 텐데 | M25: 그렇네 그 정도만 돼도 좋을 텐데 철물 구조 그거 되게 비쌌을 텐데. | N25: 그런네 그 정도만 돼도 조을 텐데 철물 구조 그거 되게 비싸쓸 텐데 | O25: form_rule_prediction | P25: resolved_form | Q25: labeled_word_slots | R25: labeled_word_slots | T25: 2022\SDRW2200000836.1.1.119.wav | U25: 2022\SDRW2200000836.1.1.119.lab | V25: 2022\SDRW2200000836.1.1.119.TextGrid | W25: 2022\SDRW2200000836.1.1.119.csv
A26: 2022 | B26: SD2201782 | C26: SDRW2200001237 | D26: SDRW2200001237.1 | E26: SD2201781 | SD2201782 | F26: 2 | G26: SD2201781 | H26: 1 | I26: SDRW2200001237.1.1.223 | J26: 나는 연락을 받았는데 자기는 안 가고 싶어하고 | K26: 나는 연락을 받았는데 자기는 안 가고 싶어하고 | L26: 나는 열라글 바단는데 자기는 안 가고 시퍼하고 | M26: 나는 연락을 받았는데 자기는 안 가고 싶어하고 | N26: 나는 열라글 바단는데 자기는 안 가고 시퍼하고 | O26: form_rule_prediction | P26: resolved_form | Q26: labeled_word_slots | R26: labeled_word_slots | T26: 2022\SDRW2200001237.1.1.223.wav | U26: 2022\SDRW2200001237.1.1.223.lab | V26: 2022\SDRW2200001237.1.1.223.TextGrid | W26: 2022\SDRW2200001237.1.1.223.csv
A27: 2022 | B27: SD2201782 | C27: SDRW2200001237 | D27: SDRW2200001237.1 | E27: SD2201781 | SD2201782 | F27: 2 | G27: SD2201781 | H27: 1 | I27: SDRW2200001237.1.1.105 | J27: 며느리 사랑은 시아버지야. | K27: 며느리 사랑은 시아버지야. | L27: 며느리 사랑은 시아버지야 | M27: 며느리 사랑은 시아버지야. | N27: 며느리 사랑은 시아버지야 | O27: form_rule_prediction | P27: resolved_form | Q27: all_lexical_slots | R27: all_lexical_slots | T27: 2022\SDRW2200001237.1.1.105.wav | U27: 2022\SDRW2200001237.1.1.105.lab | V27: 2022\SDRW2200001237.1.1.105.TextGrid | W27: 2022\SDRW2200001237.1.1.105.csv
A28: 2022 | B28: SD2202054 | C28: SDRW2200001570 | D28: SDRW2200001570.1 | E28: SD2202054 | SD2202055 | F28: 2 | G28: SD2202055 | H28: 1 | I28: SDRW2200001570.1.1.280 | J28: 그렇다고 우리 세금을 낼 수 이 우예 | K28: 그렇다고 우리 세금을 낼 수 이 ((우예)) | L28: 그러타고 우리 세그믈 낼 수 이 우예 | M28: 그렇다고 우리 세금을 낼 수 이 우예 | N28: 그러타고 우리 세그믈 낼 수 이 우예 | O28: form_rule_prediction | P28: resolved_form | Q28: labeled_word_slots | R28: labeled_word_slots | T28: 2022\SDRW2200001570.1.1.280.wav | U28: 2022\SDRW2200001570.1.1.280.lab | V28: 2022\SDRW2200001570.1.1.280.TextGrid | W28: 2022\SDRW2200001570.1.1.280.csv
... A36: 2023 | B36: SD2301983 | C36: SDRW2300001859 | D36: SDRW2300001859.1 | E36: SD2301982 | SD2301983 | F36: 2 | G36: SD2301982 | H36: 1 | I36: SDRW2300001859.1.1.109 | J36: 어떻게 두시고 투자를 하시는 타입이신가요? | K36: 어떻게 두시고 투자를 하시는 타입이신가요? | L36: 어떠케 두시고 투자를 하시는 타이비신가요 | M36: 어떻게 두시고 투자를 하시는 타입이신가요? | N36: 어떠케 두시고 투자를 하시는 타이비신가요 | O36: form_rule_prediction | P36: resolved_form | Q36: labeled_word_slots | R36: labeled_word_slots | T36: 2023\SDRW2300001859.1.1.109.wav | U36: 2023\SDRW2300001859.1.1.109.lab | V36: 2023\SDRW2300001859.1.1.109.TextGrid | W36: 2023\SDRW2300001859.1.1.109.csv
A37: 2023 | B37: SD2301983 | C37: SDRW2300001859 | D37: SDRW2300001859.1 | E37: SD2301982 | SD2301983 | F37: 2 | G37: SD2301982 | H37: 1 | I37: SDRW2300001859.1.1.108 | J37: 장기 단기 이런 기간을 | K37: 장기 단기 이런 {laughing} 기간을 | L37: 장기 단기 이런 기가늘 | M37: 장기 단기 이런 기간을 | N37: 장기 단기 이런 기가늘 | O37: form_rule_prediction | P37: resolved_form | Q37: utterance_fallback | R37: labeled_word_slots | S37: original_form: tokens=5, lexical_slots=7, labeled_slots=4 | T37: 2023\SDRW2300001859.1.1.108.wav | U37: 2023\SDRW2300001859.1.1.108.lab | V37: 2023\SDRW2300001859.1.1.108.TextGrid | W37: 2023\SDRW2300001859.1.1.108.csv
A38: 2023 | B38: SD2302149 | C38: SDRW2300001955 | D38: SDRW2300001955.1 | E38: SD2302148 | SD2302149 | F38: 2 | G38: SD2302148 | H38: 1 | I38: SDRW2300001955.1.1.164 | J38: 어 접근하려고 좀 노력을 하고 있습니다. | K38: 어~ 접근할려고 쫌 노력을 하고 있습니다. | L38: 어 접끈하려고 좀 노려글 하고 읻씀니다 | M38: 어 접근하려고 좀 노력을 하고 있습니다. | N38: 어 접끈하려고 좀 노려글 하고 읻씀니다 | O38: form_rule_prediction | P38: resolved_form | Q38: labeled_word_slots | R38: labeled_word_slots | T38: 2023\SDRW2300001955.1.1.164.wav | U38: 2023\SDRW2300001955.1.1.164.lab | V38: 2023\SDRW2300001955.1.1.164.TextGrid | W38: 2023\SDRW2300001955.1.1.164.csv
A39: 2023 | B39: SD2302149 | C39: SDRW2300001955 | D39: SDRW2300001955.1 | E39: SD2302148 | SD2302149 | F39: 2 | G39: SD2302148 | H39: 1 | I39: SDRW2300001955.1.1.11 | J39: 어 월세 전세 이런 뭐 매물들을 다루다 보니까 | K39: 어~ 월세 전세 이런 뭐~ 매물들을 다루다 보니까 | L39: 어 월세 전세 이런 뭐 매물드를 다루다 보니까 | M39: 어 월세 전세 이런 뭐 매물들을 다루다 보니까 | N39: 어 월세 전세 이런 뭐 매물드를 다루다 보니까 | O39: form_rule_prediction | P39: resolved_form | Q39: labeled_word_slots | R39: labeled_word_slots | T39: 2023\SDRW2300001955.1.1.11.wav | U39: 2023\SDRW2300001955.1.1.11.lab | V39: 2023\SDRW2300001955.1.1.11.TextGrid | W39: 2023\SDRW2300001955.1.1.11.csv
A40: 2023 | B40: SD2310934 | C40: SDRW2300000891 | D40: SDRW2300000891.1 | E40: SD2300935 | SD2310934 | F40: 2 | G40: SD2300935 | H40: 1 | I40: SDRW2300000891.1.1.331 | J40: 무조건 1층으로 된 집에서 살고 싶어. | K40: 무조건 일 층으로 된 집에서 살고 싶어. | L40: 무조건 ∅ 된 지베서 살고 시퍼 | M40: 무조건 일 층으로 된 집에서 살고 싶어. | N40: 무조건 일 층으로 된 지베서 살고 시퍼 | O40: original_form_placeholder_resolution | P40: resolved_original_form | Q40: all_lexical_slots | R40: all_lexical_slots | T40: 2023\SDRW2300000891.1.1.331.wav | U40: 2023\SDRW2300000891.1.1.331.lab | V40: 2023\SDRW2300000891.1.1.331.TextGrid | W40: 2023\SDRW2300000891.1.1.331.csv
A41: 2023 | B41: SD2310934 | C41: SDRW2300000891 | D41: SDRW2300000891.1 | E41: SD2300935 | SD2310934 | F41: 2 | G41: SD2300935 | H41: 1 | I41: SDRW2300000891.1.1.229 | J41: 가지고 싶은 소품이나 아니면 이런 걸 놓을 공간이 있으면 좋겠다. | K41: 가지고 싶은 소품이나 아니면 이런 걸 놓을 공간이 있으면 좋겠다. | L41: 가지고 시픈 소푸미나 아니면 이런 걸 노을 공가니 이쓰면 조켇따 | M41: 가지고 싶은 소품이나 아니면 이런 걸 놓을 공간이 있으면 좋겠다. | N41: 가지고 시픈 소푸미나 아니면 이런 걸 노을 공가니 이쓰면 조켇따 | O41: form_rule_prediction | P41: resolved_form | Q41: labeled_word_slots | R41: labeled_word_slots | T41: 2023\SDRW2300000891.1.1.229.wav | U41: 2023\SDRW2300000891.1.1.229.lab | V41: 2023\SDRW2300000891.1.1.229.TextGrid | W41: 2023\SDRW2300000891.1.1.229.csv
A42: 2024 | B42: SD2400795 | C42: SDRW2400001098 | D42: SDRW2400001098.1 | E42: SD2400795 | SD2400796 | F42: 2 | G42: SD2400796 | H42: 1 | I42: SDRW2400001098.1.1.64 | J42: 그 요즘 택배 중에 그렇게 어 | K42: 그 요즘 택배 중에 그릏게 어~ | L42: 그 요즘 택빼 중에 그러케 어 | M42: 그 요즘 택배 중에 그렇게 어 | N42: 그 요즘 택빼 중에 그러케 어 | O42: form_rule_prediction | P42: resolved_form | Q42: labeled_word_slots | R42: labeled_word_slots | T42: 2024\SDRW2400001098.1.1.64.wav | U42: 2024\SDRW2400001098.1.1.64.lab | V42: 2024\SDRW2400001098.1.1.64.TextGrid | W42: 2024\SDRW2400001098.1.1.64.csv
A43: 2024 | B43: SD2400795 | C43: SDRW2400001098 | D43: SDRW2400001098.1 | E43: SD2400795 | SD2400796 | F43: 2 | G43: SD2400796 | H43: 1 | I43: SDRW2400001098.1.1.92 | J43: 어 그게 이제 어도비에서 제공하는 모든 프로그램을 이용할 수 있는 이제 | K43: 어 그게 이제 어도비에서 제공하는 모든 프로그램을 이용할 수 있는 이제 | L43: 어 그게 이제 어도비에서 제공하는 모든 프로그래믈 이용할 수 인는 이제 | M43: 어 그게 이제 어도비에서 제공하는 모든 프로그램을 이용할 수 있는 이제 | N43: 어 그게 이제 어도비에서 제공하는 모든 프로그래믈 이용할 수 인는 이제 | O43: form_rule_prediction | P43: resolved_form | Q43: labeled_word_slots | R43: labeled_word_slots | T43: 2024\SDRW2400001098.1.1.92.wav | U43: 2024\SDRW2400001098.1.1.92.lab | V43: 2024\SDRW2400001098.1.1.92.TextGrid | W43: 2024\SDRW2400001098.1.1.92.csv
A44: 2024 | B44: SD2400841 | C44: SDRW2400000324 | D44: SDRW2400000324.1 | E44: SD2400839 | SD2400840 | SD2400841 | F44: 3 | G44: SD2400839 | SD2400840 | H44: 2 | I44: SDRW2400000324.1.1.170 | J44: 나는 약간 그 스카이 캐슬의 내용 중에서 이제 어떤 한 아이 아이들의 어머니가 아버지에게 이제 큰 음 약간 가정 폭력 비슷한 거를 이제 당하는 장면에서 | K44: 나는 약간 그~ 스카이 캐쓸에 내용 중에서 이제 어떤 한 -아이- 아이들에 어머니가 아버지에게 이제 큰 음~ 약간 가정 폭력 비슷한 거를 이제 당하는 장면에서 | L44: 나는 약깐 그 스카이 캐스릐 내용 중에서 이제 어떤 한 아이 아이드릐 어머니가 아버지에게 이제 큰 음 약깐 가정 폭력 비스탄 거를 이제 당하는 장며네서 | M44: 나는 약간 그 스카이 캐슬의 내용 중에서 이제 어떤 한 아이 아이들의 어머니가 아버지에게 이제 큰 음 약간 가정 폭력 비슷한 거를 이제 당하는 장면에서 | N44: 나는 약깐 그 스카이 캐스릐 내용 중에서 이제 어떤 한 아이 아이드릐 어머니가 아버지에게 이제 큰 음 약깐 가정 폭력 비스탄 거를 이제 당하는 장며네서 | O44: form_rule_prediction | P44: resolved_form | Q44: labeled_word_slots | R44: labeled_word_slots | T44: 2024\SDRW2400000324.1.1.170.wav | U44: 2024\SDRW2400000324.1.1.170.lab | V44: 2024\SDRW2400000324.1.1.170.TextGrid | W44: 2024\SDRW2400000324.1.1.170.csv
A45: 2024 | B45: SD2400841 | C45: SDRW2400000324 | D45: SDRW2400000324.1 | E45: SD2400839 | SD2400840 | SD2400841 | F45: 3 | G45: SD2400839 | SD2400840 | H45: 2 | I45: SDRW2400000324.1.1.30 | J45: 그것도 해리 포터 작가와 같은 롤랭 롤랭 조인 뭐 이름은 잘 모르겠지만 | K45: 그것도 해리 포터 작가와 같은 롤랭 롤랭 조인 뭐~ 이름은 잘 모르겠지만 | L45: 그걷또 해리 포터 작까와 가튼 롤랭 롤랭 조인 뭐 이르믄 잘 모르겓찌만 | M45: 그것도 해리 포터 작가와 같은 롤랭 롤랭 조인 뭐 이름은 잘 모르겠지만 | N45: 그걷또 해리 포터 작까와 가튼 롤랭 롤랭 조인 뭐 이르믄 잘 모르겓찌만 | O45: form_rule_prediction | P45: resolved_form | Q45: labeled_word_slots | R45: labeled_word_slots | T45: 2024\SDRW2400000324.1.1.30.wav | U45: 2024\SDRW2400000324.1.1.30.lab | V45: 2024\SDRW2400000324.1.1.30.TextGrid | W45: 2024\SDRW2400000324.1.1.30.csv
A46: 2024 | B46: SD2401102 | C46: SDRW2400001368 | D46: SDRW2400001368.1 | E46: SD2401101 | SD2401102 | F46: 2 | G46: SD2401101 | H46: 1 | I46: SDRW2400001368.1.1.121 | J46: 홈 쇼핑에서 사는 게 어려워지는 것 같아. | K46: 홈 쑈핑에서 사는 게 어려워지는 거 같애. | L46: 홈 쇼핑에서 사는 게 어려워지는 걷 가타 | M46: 홈 쇼핑에서 사는 게 어려워지는 것 같아. | N46: 홈 쇼핑에서 사는 게 어려워지는 걷 가타 | O46: form_rule_prediction | P46: resolved_form | Q46: all_lexical_slots | R46: all_lexical_slots | T46: 2024\SDRW2400001368.1.1.121.wav | U46: 2024\SDRW2400001368.1.1.121.lab | V46: 2024\SDRW2400001368.1.1.121.TextGrid | W46: 2024\SDRW2400001368.1.1.121.csv
A47: 2024 | B47: SD2401102 | C47: SDRW2400001368 | D47: SDRW2400001368.1 | E47: SD2401101 | SD2401102 | F47: 2 | G47: SD2401101 | H47: 1 | I47: SDRW2400001368.1.1.105 | J47: 혜택적인 부분도 내가 엄마가 직접적으로 듣고 바로 구매할 수 있는 | K47: 혜택적인 부분두 내가 엄마가 직접적으로 듣고 바로 구매할 수 있는 | L47: 혜택쩌긴 부분도 내가 엄마가 직쩝쩌그로 듣꼬 바로 구매할 수 인는 | M47: 혜택적인 부분도 내가 엄마가 직접적으로 듣고 바로 구매할 수 있는 | N47: 혜택쩌긴 부분도 내가 엄마가 직쩝쩌그로 듣꼬 바로 구매할 수 인는 | O47: form_rule_prediction | P47: resolved_form | Q47: labeled_word_slots | R47: labeled_word_slots | T47: 2024\SDRW2400001368.1.1.105.wav | U47: 2024\SDRW2400001368.1.1.105.lab | V47: 2024\SDRW2400001368.1.1.105.TextGrid | W47: 2024\SDRW2400001368.1.1.105.csv
A48: 2024 | B48: SD2401137 | C48: SDRW2400001439 | D48: SDRW2400001439.1 | E48: SD2401137 | SD2401138 | F48: 2 | G48: SD2401138 | H48: 1 | I48: SDRW2400001439.1.1.152 | J48: 어 그렇긴 해. | K48: 어 그렇긴 해. | L48: 어 그러킨 해 | M48: 어 그렇긴 해. | N48: 어 그러킨 해 | O48: form_rule_prediction | P48: resolved_form | Q48: all_lexical_slots | R48: all_lexical_slots | T48: 2024\SDRW2400001439.1.1.152.wav | U48: 2024\SDRW2400001439.1.1.152.lab | V48: 2024\SDRW2400001439.1.1.152.TextGrid | W48: 2024\SDRW2400001439.1.1.152.csv
...

Sheet 선택값
A1: 범주 | B1: 값
A2: 음성-문장 | B2: 일치
A3: 음성-문장 | B3: 불일치
A4: 음성-문장 | B4: 판단 불가
A5: 품질 | B5: 양호
A6: 품질 | B6: 수정 필요
A7: 품질 | B7: 판단 불가
A8: 종합 | B8: 통과
A9: 종합 | B9: 수정 필요
A10: 종합 | B10: 보류
A11: 재검토 | B11: 아니오
A12: 재검토 | B12: 예
